<?xml version="1.0" ?>
<sdf version="1.8">
  <model name="vio_robot">
    <pose>0 0 0.1 0 0 0</pose>

    <link name="base_link">
      <inertial>
        <mass>1.0</mass>
        <inertia>
          <ixx>0.01</ixx><ixy>0</ixy><ixz>0</ixz>
          <iyy>0.01</iyy><iyz>0</iyz>
          <izz>0.01</izz>
        </inertia>
      </inertial>
      <visual name="visual">
        <geometry><box><size>0.3 0.3 0.1</size></box></geometry>
        <material><ambient>0.1 0.1 0.1 1</ambient></material>
      </visual>
      <collision name="collision">
        <geometry><box><size>0.3 0.3 0.1</size></box></geometry>
      </collision>
    </link>

    <!-- Left Wheel -->
    <link name="left_wheel">
      <pose>0 0.17 0 -1.5707 0 0</pose>
      <inertial>
        <mass>0.1</mass>
        <inertia>
          <ixx>0.001</ixx><iyy>0.001</iyy><izz>0.001</izz>
        </inertia>
      </inertial>
      <visual name="visual">
        <geometry><cylinder><radius>0.1</radius><length>0.04</length></cylinder></geometry>
        <material><ambient>0.2 0.2 0.2 1</ambient></material>
      </visual>
      <collision name="collision">
        <geometry><cylinder><radius>0.1</radius><length>0.04</length></cylinder></geometry>
        <surface>
          <friction>
            <ode><mu>1.0</mu><mu2>1.0</mu2></ode>
          </friction>
        </surface>
      </collision>
    </link>

    <joint name="left_wheel_joint" type="revolute">
      <parent>base_link</parent>
      <child>left_wheel</child>
      <axis>
        <xyz>0 0 1</xyz>
        <limit><lower>-1.79769e+308</lower><upper>1.79769e+308</upper></limit>
      </axis>
    </joint>

    <!-- Right Wheel -->
    <link name="right_wheel">
      <pose>0 -0.17 0 -1.5707 0 0</pose>
      <inertial>
        <mass>0.1</mass>
        <inertia>
          <ixx>0.001</ixx><iyy>0.001</iyy><izz>0.001</izz>
        </inertia>
      </inertial>
      <visual name="visual">
        <geometry><cylinder><radius>0.1</radius><length>0.04</length></cylinder></geometry>
        <material><ambient>0.2 0.2 0.2 1</ambient></material>
      </visual>
      <collision name="collision">
        <geometry><cylinder><radius>0.1</radius><length>0.04</length></cylinder></geometry>
        <surface>
          <friction>
            <ode><mu>1.0</mu><mu2>1.0</mu2></ode>
          </friction>
        </surface>
      </collision>
    </link>

    <joint name="right_wheel_joint" type="revolute">
      <parent>base_link</parent>
      <child>right_wheel</child>
      <axis>
        <xyz>0 0 1</xyz>
        <limit><lower>-1.79769e+308</lower><upper>1.79769e+308</upper></limit>
      </axis>
    </joint>

    <!-- Caster Wheel (for stability) -->
    <link name="caster">
      <pose>-0.1 0 -0.05 0 0 0</pose>
      <inertial>
        <mass>0.05</mass>
        <inertia>
          <ixx>0.0001</ixx><iyy>0.0001</iyy><izz>0.0001</izz>
        </inertia>
      </inertial>
      <visual name="visual">
        <geometry><sphere><radius>0.05</radius></sphere></geometry>
        <material><ambient>0.3 0.3 0.3 1</ambient></material>
      </visual>
      <collision name="collision">
        <geometry><sphere><radius>0.05</radius></sphere></geometry>
        <surface>
          <friction><ode><mu>0.0</mu><mu2>0.0</mu2></ode></friction>
        </surface>
      </collision>
    </link>

    <joint name="caster_joint" type="fixed">
      <parent>base_link</parent>
      <child>caster</child>
    </joint>

    <!-- IMU Link & Sensor -->
    <link name="imu_link">
      <pose>0 0 0.05 0 0 0</pose>
      <inertial>
        <mass>0.01</mass>
        <inertia>
          <ixx>0.0001</ixx><iyy>0.0001</iyy><izz>0.0001</izz>
        </inertia>
      </inertial>
      <sensor name="imu_sensor" type="imu">
        <always_on>true</always_on>
        <update_rate>200</update_rate>
        <visualize>true</visualize>
        <topic>/imu</topic>
      </sensor>
    </link>

    <joint name="imu_joint" type="fixed">
      <parent>base_link</parent>
      <child>imu_link</child>
    </joint>

    <!-- Camera Link & Sensor -->
    <link name="camera_link">
      <pose>0.15 0 0.1 0 0 0</pose>
      <inertial>
        <mass>0.1</mass>
        <inertia><ixx>0.001</ixx><iyy>0.001</iyy><izz>0.001</izz></inertia>
      </inertial>
      <visual name="cam_visual">
        <geometry><box><size>0.05 0.05 0.05</size></box></geometry>
        <material><ambient>0 0 1 1</ambient></material>
      </visual>
      <sensor name="camera" type="camera">
        <pose>0 0 0 0 0 0</pose>
        <camera>
          <horizontal_fov>1.047</horizontal_fov>
          <image><width>640</width><height>480</height></image>
          <clip><near>0.1</near><far>100</far></clip>
        </camera>
        <always_on>true</always_on>
        <update_rate>30</update_rate>
        <visualize>true</visualize>
        <topic>/camera</topic>
      </sensor>
    </link>

    <joint name="camera_joint" type="fixed">
      <parent>base_link</parent>
      <child>camera_link</child>
    </joint>

    <!-- Diff Drive Plugin -->
    <plugin
      filename="ignition-gazebo-diff-drive-system"
      name="ignition::gazebo::systems::DiffDrive">
      <left_joint>left_wheel_joint</left_joint>
      <right_joint>right_wheel_joint</right_joint>
      <wheel_separation>0.34</wheel_separation>
      <wheel_radius>0.1</wheel_radius>
      <odom_publish_frequency>50</odom_publish_frequency>
      <topic>cmd_vel</topic>
    </plugin>

    <plugin filename="libignition-gazebo-pose-publisher-system.so"
            name="ignition::gazebo::systems::PosePublisher">
      <publish_link_pose>true</publish_link_pose>
      <publish_sensor_pose>true</publish_sensor_pose>
      <publish_collision_pose>false</publish_collision_pose>
      <publish_visual_pose>false</publish_visual_pose>
      <publish_nested_model_pose>false</publish_nested_model_pose>
      <use_pose_vector_msg>true</use_pose_vector_msg>
      <static_publisher>true</static_publisher>
      <static_update_frequency>1</static_update_frequency>
      <update_frequency>50</update_frequency>
    </plugin>
  </model>
</sdf>
